Workbook

Sheet Node
A1: id | B1: type | C1: pressure(MPa) | D1: injection(kg/s) | E1: T(Celsius) | F1: remark | G1: my_type
A2: 1 | B2: 定压力 | C2: 0.2 | E2: 55 | F2: 供水网
A3: 2 | B3: 定注入 | F3: 供水网
A4: 3 | B4: 定注入 | F4: 供水网
A5: 4 | B5: 定注入 | F5: 供水网
A6: 5 | B6: 定注入 | F6: 供水网
A7: 6 | B7: 定注入 | F7: 供水网
A8: 7 | B8: 定注入 | F8: 供水网
A9: 8 | B9: 定注入 | F9: 供水网
A10: 9 | B10: 定注入 | F10: 供水网
A11: 10 | B11: 定注入 | F11: 供水网
A12: 11 | B12: 定注入 | F12: 供水网
A13: 12 | B13: 定注入 | F13: 供水网
A14: 13 | B14: 定注入 | F14: 供水网
... A31: 30 | B31: 定注入 | F31: 供水网
A32: 31 | B32: 定注入 | D32: =-246.085714285714/3.6 -> -68.357143 | F32: 回水网 | G32: outlet
A33: 32 | B33: 定注入 | F33: 回水网
A34: 33 | B34: 定注入 | F34: 回水网
A35: 34 | B35: 定注入 | F35: 回水网
A36: 35 | B36: 定注入 | F36: 回水网
A37: 36 | B37: 定注入 | F37: 回水网
A38: 37 | B38: 定注入 | F38: 回水网
A39: 38 | B39: 定注入 | F39: 回水网
A40: 39 | B40: 定注入 | F40: 回水网
A41: 40 | B41: 定注入 | F41: 回水网
A42: 41 | B42: 定注入 | F42: 回水网
A43: 42 | B43: 定注入 | F43: 回水网
A44: 43 | B44: 定注入 | F44: 回水网
... A61: 60 | B61: 定注入 | F61: 回水网

Sheet Branch
A1: id | B1: from node | C1: to node | D1: length | E1: diameter | F1: fraction | G1: disspation | H1: valve | I1: pump | J1: remark | K1: l_R
A2: 1 | B2: 1 | C2: 2 | D2: 75 | E2: =管径设计!D3 -> 300 | F2: =1/(1.14+2*LOG10((E2/0.5)))^2 -> 0.022301284 | G2: =3.14*E2/1000/(0.03/0.023+0.01/0.5+1/1500+1/100) -> 0.70561032 | J2: 供水网 | K2: =RANDBETWEEN(30,100) -> 57
A3: 2 | B3: 2 | C3: 3 | D3: 93 | E3: =管径设计!D4 -> 300 | F3: =1/(1.14+2*LOG10((E3/0.5)))^2 -> 0.022301284 | G3: =3.14*E3/1000/(0.03/0.023+0.01/0.5+1/1500+1/100) -> 0.70561032 | J3: 供水网 | K3: =RANDBETWEEN(30,100) -> 95
A4: 3 | B4: 3 | C4: 4 | D4: 37 | E4: =管径设计!D5 -> 300 | F4: =1/(1.14+2*LOG10((E4/0.5)))^2 -> 0.022301284 | G4: =3.14*E4/1000/(0.03/0.023+0.01/0.5+1/1500+1/100) -> 0.70561032 | J4: 供水网 | K4: =RANDBETWEEN(30,100) -> 34
A5: 4 | B5: 4 | C5: 5 | D5: 72 | E5: =管径设计!D6 -> 250 | F5: =1/(1.14+2*LOG10((E5/0.5)))^2 -> 0.023394735 | G5: =3.14*E5/1000/(0.03/0.023+0.01/0.5+1/1500+1/100) -> 0.5880086 | J5: 供水网 | K5: =RANDBETWEEN(30,100) -> 59
A6: 5 | B6: 5 | C6: 6 | D6: 34 | E6: =管径设计!D7 -> 250 | F6: =1/(1.14+2*LOG10((E6/0.5)))^2 -> 0.023394735 | G6: =3.14*E6/1000/(0.03/0.023+0.01/0.5+1/1500+1/100) -> 0.5880086 | J6: 供水网 | K6: =RANDBETWEEN(30,100) -> 83
A7: 6 | B7: 6 | C7: 7 | D7: 50 | E7: =管径设计!D8 -> 250 | F7: =1/(1.14+2*LOG10((E7/0.5)))^2 -> 0.023394735 | G7: =3.14*E7/1000/(0.03/0.023+0.01/0.5+1/1500+1/100) -> 0.5880086 | J7: 供水网 | K7: =RANDBETWEEN(30,100) -> 83
A8: 7 | B8: 7 | C8: 8 | D8: 50 | E8: =管径设计!D9 -> 250 | F8: =1/(1.14+2*LOG10((E8/0.5)))^2 -> 0.023394735 | G8: =3.14*E8/1000/(0.03/0.023+0.01/0.5+1/1500+1/100) -> 0.5880086 | J8: 供水网 | K8: =RANDBETWEEN(30,100) -> 90
A9: 8 | B9: 8 | C9: 9 | D9: 96 | E9: =管径设计!D10 -> 250 | F9: =1/(1.14+2*LOG10((E9/0.5)))^2 -> 0.023394735 | G9: =3.14*E9/1000/(0.03/0.023+0.01/0.5+1/1500+1/100) -> 0.5880086 | J9: 供水网 | K9: =RANDBETWEEN(30,100) -> 70
A10: 9 | B10: 9 | C10: 10 | D10: 83 | E10: =管径设计!D11 -> 250 | F10: =1/(1.14+2*LOG10((E10/0.5)))^2 -> 0.023394735 | G10: =3.14*E10/1000/(0.03/0.023+0.01/0.5+1/1500+1/100) -> 0.5880086 | J10: 供水网 | K10: =RANDBETWEEN(30,100) -> 83
A11: 10 | B11: 10 | C11: 11 | D11: 37 | E11: =管径设计!D12 -> 250 | F11: =1/(1.14+2*LOG10((E11/0.5)))^2 -> 0.023394735 | G11: =3.14*E11/1000/(0.03/0.023+0.01/0.5+1/1500+1/100) -> 0.5880086 | J11: 供水网 | K11: =RANDBETWEEN(30,100) -> 91
A12: 11 | B12: 11 | C12: 12 | D12: 76 | E12: =管径设计!D13 -> 250 | F12: =1/(1.14+2*LOG10((E12/0.5)))^2 -> 0.023394735 | G12: =3.14*E12/1000/(0.03/0.023+0.01/0.5+1/1500+1/100) -> 0.5880086 | J12: 供水网 | K12: =RANDBETWEEN(30,100) -> 61
A13: 12 | B13: 12 | C13: 13 | D13: 81 | E13: =管径设计!D14 -> 200 | F13: =1/(1.14+2*LOG10((E13/0.5)))^2 -> 0.024846043 | G13: =3.14*E13/1000/(0.03/0.023+0.01/0.5+1/1500+1/100) -> 0.47040688 | J13: 供水网 | K13: =RANDBETWEEN(30,100) -> 70
... A15: 14 | B15: 14 | C15: 15 | D15: 77 | E15: =管径设计!D16 -> 150 | F15: =1/(1.14+2*LOG10((E15/0.5)))^2 -> 0.026925299 | G15: =3.14*E15/1000/(0.03/0.023+0.01/0.5+1/1500+1/100) -> 0.35280516 | J15: 供水网 | K15: =RANDBETWEEN(30,100) -> 55
A16: 15 | B16: 15 | C16: 30 | D16: 81 | E16: =管径设计!D17 -> 100 | F16: =1/(1.14+2*LOG10((E16/0.5)))^2 -> 0.030329451 | G16: =3.14*E16/1000/(0.03/0.023+0.01/0.5+1/1500+1/100) -> 0.23520344 | H16: 15 | J16: 供水网 | K16: =RANDBETWEEN(30,100) -> 71
A17: 16 | B17: 2 | C17: 16 | D17: 38 | E17: =管径设计!D20 -> 65 | F17: =1/(1.14+2*LOG10((E17/0.5)))^2 -> 0.034705101 | G17: =3.14*E17/1000/(0.03/0.023+0.01/0.5+1/1500+1/100) -> 0.15288224 | H17: 1 | J17: 供水网 | K17: =RANDBETWEEN(30,100) -> 97
A18: 17 | B18: 3 | C18: 17 | D18: 71 | E18: =管径设计!D21 -> 65 | F18: =1/(1.14+2*LOG10((E18/0.5)))^2 -> 0.034705101 | G18: =3.14*E18/1000/(0.03/0.023+0.01/0.5+1/1500+1/100) -> 0.15288224 | H18: 2 | J18: 供水网 | K18: =RANDBETWEEN(30,100) -> 89
A19: 18 | B19: 4 | C19: 18 | D19: 40 | E19: =管径设计!D22 -> 100 | F19: =1/(1.14+2*LOG10((E19/0.5)))^2 -> 0.030329451 | G19: =3.14*E19/1000/(0.03/0.023+0.01/0.5+1/1500+1/100) -> 0.23520344 | H19: 3 | J19: 供水网 | K19: =RANDBETWEEN(30,100) -> 95
A20: 19 | B20: 5 | C20: 19 | D20: 40 | E20: =管径设计!D23 -> 50 | F20: =1/(1.14+2*LOG10((E20/0.5)))^2 -> 0.037850687 | G20: =3.14*E20/1000/(0.03/0.023+0.01/0.5+1/1500+1/100) -> 0.11760172 | H20: 4 | J20: 供水网 | K20: =RANDBETWEEN(30,100) -> 32
A21: 20 | B21: 6 | C21: 20 | D21: 78 | E21: =管径设计!D24 -> 80 | F21: =1/(1.14+2*LOG10((E21/0.5)))^2 -> 0.032485498 | G21: =3.14*E21/1000/(0.03/0.023+0.01/0.5+1/1500+1/100) -> 0.18816275 | H21: 5 | J21: 供水网 | K21: =RANDBETWEEN(30,100) -> 97
A22: 21 | B22: 7 | C22: 21 | D22: 94 | E22: =管径设计!D25 -> 65 | F22: =1/(1.14+2*LOG10((E22/0.5)))^2 -> 0.034705101 | G22: =3.14*E22/1000/(0.03/0.023+0.01/0.5+1/1500+1/100) -> 0.15288224 | H22: 6 | J22: 供水网 | K22: =RANDBETWEEN(30,100) -> 96
A23: 22 | B23: 8 | C23: 22 | D23: 32 | E23: =管径设计!D26 -> 65 | F23: =1/(1.14+2*LOG10((E23/0.5)))^2 -> 0.034705101 | G23: =3.14*E23/1000/(0.03/0.023+0.01/0.5+1/1500+1/100) -> 0.15288224 | H23: 7 | J23: 供水网 | K23: =RANDBETWEEN(30,100) -> 33
A24: 23 | B24: 9 | C24: 23 | D24: 61 | E24: =管径设计!D27 -> 65 | F24: =1/(1.14+2*LOG10((E24/0.5)))^2 -> 0.034705101 | G24: =3.14*E24/1000/(0.03/0.023+0.01/0.5+1/1500+1/100) -> 0.15288224 | H24: 8 | J24: 供水网 | K24: =RANDBETWEEN(30,100) -> 72
A25: 24 | B25: 10 | C25: 24 | D25: 46 | E25: =管径设计!D28 -> 65 | F25: =1/(1.14+2*LOG10((E25/0.5)))^2 -> 0.034705101 | G25: =3.14*E25/1000/(0.03/0.023+0.01/0.5+1/1500+1/100) -> 0.15288224 | H25: 9 | J25: 供水网 | K25: =RANDBETWEEN(30,100) -> 32
A26: 25 | B26: 11 | C26: 25 | D26: 58 | E26: =管径设计!D29 -> 100 | F26: =1/(1.14+2*LOG10((E26/0.5)))^2 -> 0.030329451 | G26: =3.14*E26/1000/(0.03/0.023+0.01/0.5+1/1500+1/100) -> 0.23520344 | H26: 10 | J26: 供水网 | K26: =RANDBETWEEN(30,100) -> 66
A27: 26 | B27: 12 | C27: 26 | D27: 33 | E27: =管径设计!D30 -> 100 | F27: =1/(1.14+2*LOG10((E27/0.5)))^2 -> 0.030329451 | G27: =3.14*E27/1000/(0.03/0.023+0.01/0.5+1/1500+1/100) -> 0.23520344 | H27: 11 | J27: 供水网 | K27: =RANDBETWEEN(30,100) -> 71
A28: 27 | B28: 13 | C28: 27 | D28: 45 | E28: =管径设计!D31 -> 100 | F28: =1/(1.14+2*LOG10((E28/0.5)))^2 -> 0.030329451 | G28: =3.14*E28/1000/(0.03/0.023+0.01/0.5+1/1500+1/100) -> 0.23520344 | H28: 12 | J28: 供水网 | K28: =RANDBETWEEN(30,100) -> 75
... A30: 29 | B30: 15 | C30: 29 | D30: 86 | E30: =管径设计!D33 -> 100 | F30: =1/(1.14+2*LOG10((E30/0.5)))^2 -> 0.030329451 | G30: =3.14*E30/1000/(0.03/0.023+0.01/0.5+1/1500+1/100) -> 0.23520344 | H30: 14 | J30: 供水网 | K30: =RANDBETWEEN(30,100) -> 94
A31: 30 | B31: =C2+30 -> 32 | C31: =B2+30 -> 31 | D31: =D2 -> 75 | E31: =E2 -> 300 | F31: =1/(1.14+2*LOG10((E31/0.5)))^2 -> 0.022301284 | G31: =3.14*E31/1000/(0.03/0.023+0.01/0.5+1/1500+1/100) -> 0.70561032 | J31: 回水网
A32: 31 | B32: =C3+30 -> 33 | C32: =B3+30 -> 32 | D32: =D3 -> 93 | E32: =E3 -> 300 | F32: =1/(1.14+2*LOG10((E32/0.5)))^2 -> 0.022301284 | G32: =3.14*E32/1000/(0.03/0.023+0.01/0.5+1/1500+1/100) -> 0.70561032 | J32: 回水网
A33: 32 | B33: =C4+30 -> 34 | C33: =B4+30 -> 33 | D33: =D4 -> 37 | E33: =E4 -> 300 | F33: =1/(1.14+2*LOG10((E33/0.5)))^2 -> 0.022301284 | G33: =3.14*E33/1000/(0.03/0.023+0.01/0.5+1/1500+1/100) -> 0.70561032 | J33: 回水网
A34: 33 | B34: =C5+30 -> 35 | C34: =B5+30 -> 34 | D34: =D5 -> 72 | E34: =E5 -> 250 | F34: =1/(1.14+2*LOG10((E34/0.5)))^2 -> 0.023394735 | G34: =3.14*E34/1000/(0.03/0.023+0.01/0.5+1/1500+1/100) -> 0.5880086 | J34: 回水网
A35: 34 | B35: =C6+30 -> 36 | C35: =B6+30 -> 35 | D35: =D6 -> 34 | E35: =E6 -> 250 | F35: =1/(1.14+2*LOG10((E35/0.5)))^2 -> 0.023394735 | G35: =3.14*E35/1000/(0.03/0.023+0.01/0.5+1/1500+1/100) -> 0.5880086 | J35: 回水网
A36: 35 | B36: =C7+30 -> 37 | C36: =B7+30 -> 36 | D36: =D7 -> 50 | E36: =E7 -> 250 | F36: =1/(1.14+2*LOG10((E36/0.5)))^2 -> 0.023394735 | G36: =3.14*E36/1000/(0.03/0.023+0.01/0.5+1/1500+1/100) -> 0.5880086 | J36: 回水网
A37: 36 | B37: =C8+30 -> 38 | C37: =B8+30 -> 37 | D37: =D8 -> 50 | E37: =E8 -> 250 | F37: =1/(1.14+2*LOG10((E37/0.5)))^2 -> 0.023394735 | G37: =3.14*E37/1000/(0.03/0.023+0.01/0.5+1/1500+1/100) -> 0.5880086 | J37: 回水网
A38: 37 | B38: =C9+30 -> 39 | C38: =B9+30 -> 38 | D38: =D9 -> 96 | E38: =E9 -> 250 | F38: =1/(1.14+2*LOG10((E38/0.5)))^2 -> 0.023394735 | G38: =3.14*E38/1000/(0.03/0.023+0.01/0.5+1/1500+1/100) -> 0.5880086 | J38: 回水网
A39: 38 | B39: =C10+30 -> 40 | C39: =B10+30 -> 39 | D39: =D10 -> 83 | E39: =E10 -> 250 | F39: =1/(1.14+2*LOG10((E39/0.5)))^2 -> 0.023394735 | G39: =3.14*E39/1000/(0.03/0.023+0.01/0.5+1/1500+1/100) -> 0.5880086 | J39: 回水网
A40: 39 | B40: =C11+30 -> 41 | C40: =B11+30 -> 40 | D40: =D11 -> 37 | E40: =E11 -> 250 | F40: =1/(1.14+2*LOG10((E40/0.5)))^2 -> 0.023394735 | G40: =3.14*E40/1000/(0.03/0.023+0.01/0.5+1/1500+1/100) -> 0.5880086 | J40: 回水网
A41: 40 | B41: =C12+30 -> 42 | C41: =B12+30 -> 41 | D41: =D12 -> 76 | E41: =E12 -> 250 | F41: =1/(1.14+2*LOG10((E41/0.5)))^2 -> 0.023394735 | G41: =3.14*E41/1000/(0.03/0.023+0.01/0.5+1/1500+1/100) -> 0.5880086 | J41: 回水网
A42: 41 | B42: =C13+30 -> 43 | C42: =B13+30 -> 42 | D42: =D13 -> 81 | E42: =E13 -> 200 | F42: =1/(1.14+2*LOG10((E42/0.5)))^2 -> 0.024846043 | G42: =3.14*E42/1000/(0.03/0.023+0.01/0.5+1/1500+1/100) -> 0.47040688 | J42: 回水网
...

Sheet Device
A1: valve-1 | B1: 2
A2: valve-2 | B2: 2
A3: valve-3 | B3: 2
A4: valve-4 | B4: 2
A5: valve-5 | B5: 2
A6: valve-6 | B6: 2
A7: valve-7 | B7: 2
A8: valve-8 | B8: 2
A9: valve-9 | B9: 2
A10: valve-10 | B10: 2
A11: valve-11 | B11: 2
A12: valve-12 | B12: 2
... A15: valve-15 | B15: 2

Sheet Building
A1: id | B1: length | C1: width | D1: height | E1: floors | F1: 供热面积 | G1: dT(C) | H1: 设计负荷(W) | I1: 目标流量(t/h) | J1: UA | K1: type | L1: 总流量 | M1: l_R | N1: W_R | O1: F_R
A2: 1 | B2: 27 | C2: 30 | D2: 3 | E2: 7 | F2: =B2*C2*E2 -> 5670 | G2: 10 | H2: =F2*50 -> 283500 | I2: =H2/1000/10/4.2*3.6 -> 24.3 | J2: =H2/(50-20)*1 -> 9450 | K2: residence | L2: =SUM(I2:I16) -> 339.67286 | M2: =RANDBETWEEN(25,45) -> 40 | N2: =RANDBETWEEN(10,30) -> 11 | O2: =RANDBETWEEN(4,15) -> 13
A3: 2 | B3: 34 | C3: 21 | D3: 3 | E3: 7 | F3: =B3*C3*E3 -> 4998 | G3: 10 | H3: =F3*50 -> 249900 | I3: =H3/1000/10/4.2*3.6 -> 21.42 | J3: =H3/(50-20)*1 -> 8330 | K3: residence | M3: =RANDBETWEEN(25,45) -> 35 | N3: =RANDBETWEEN(10,30) -> 13 | O3: =RANDBETWEEN(4,15) -> 9
A4: 3 | B4: 31 | C4: 22 | D4: 3 | E4: 15 | F4: =B4*C4*E4 -> 10230 | G4: 10 | H4: =F4*50 -> 511500 | I4: =H4/1000/10/4.2*3.6 -> 43.842857 | J4: =H4/(50-20)*1 -> 17050 | K4: residence | M4: =RANDBETWEEN(25,45) -> 37 | N4: =RANDBETWEEN(10,30) -> 12 | O4: =RANDBETWEEN(4,15) -> 8
A5: 4 | B5: 44 | C5: 14 | D5: 3 | E5: 4 | F5: =B5*C5*E5 -> 2464 | G5: 10 | H5: =F5*50 -> 123200 | I5: =H5/1000/10/4.2*3.6 -> 10.56 | J5: =H5/(50-20)*1 -> 4106.6667 | K5: residence | M5: =RANDBETWEEN(25,45) -> 38 | N5: =RANDBETWEEN(10,30) -> 22 | O5: =RANDBETWEEN(4,15) -> 7
A6: 5 | B6: 25 | C6: 17 | D6: 3 | E6: 14 | F6: =B6*C6*E6 -> 5950 | G6: 10 | H6: =F6*50 -> 297500 | I6: =H6/1000/10/4.2*3.6 -> 25.5 | J6: =H6/(50-20)*1 -> 9916.6667 | K6: residence | M6: =RANDBETWEEN(25,45) -> 31 | N6: =RANDBETWEEN(10,30) -> 16 | O6: =RANDBETWEEN(4,15) -> 6
A7: 6 | B7: 39 | C7: 18 | D7: 3 | E7: 4 | F7: =B7*C7*E7 -> 2808 | G7: 10 | H7: =F7*50 -> 140400 | I7: =H7/1000/10/4.2*3.6 -> 12.034286 | J7: =H7/(50-20)*1 -> 4680 | K7: residence | M7: =RANDBETWEEN(25,45) -> 32 | N7: =RANDBETWEEN(10,30) -> 28 | O7: =RANDBETWEEN(4,15) -> 15
A8: 7 | B8: 25 | C8: 22 | D8: 3 | E8: 5 | F8: =B8*C8*E8 -> 2750 | G8: 10 | H8: =F8*50 -> 137500 | I8: =H8/1000/10/4.2*3.6 -> 11.785714 | J8: =H8/(50-20)*1 -> 4583.3333 | K8: residence | M8: =RANDBETWEEN(25,45) -> 44 | N8: =RANDBETWEEN(10,30) -> 29 | O8: =RANDBETWEEN(4,15) -> 12
A9: 8 | B9: 29 | C9: 29 | D9: 3 | E9: 4 | F9: =B9*C9*E9 -> 3364 | G9: 10 | H9: =F9*50 -> 168200 | I9: =H9/1000/10/4.2*3.6 -> 14.417143 | J9: =H9/(50-20)*1 -> 5606.6667 | K9: residence | M9: =RANDBETWEEN(25,45) -> 37 | N9: =RANDBETWEEN(10,30) -> 16 | O9: =RANDBETWEEN(4,15) -> 15
A10: 9 | B10: 28 | C10: 15 | D10: 3 | E10: 6 | F10: =B10*C10*E10 -> 2520 | G10: 10 | H10: =F10*50 -> 126000 | I10: =H10/1000/10/4.2*3.6 -> 10.8 | J10: =H10/(50-20)*1 -> 4200 | K10: residence | M10: =RANDBETWEEN(25,45) -> 44 | N10: =RANDBETWEEN(10,30) -> 23 | O10: =RANDBETWEEN(4,15) -> 4
A11: 10 | B11: 45 | C11: 23 | D11: 3 | E11: 7 | F11: =B11*C11*E11 -> 7245 | G11: 10 | H11: =F11*50 -> 362250 | I11: =H11/1000/10/4.2*3.6 -> 31.05 | J11: =H11/(50-20)*1 -> 12075 | K11: residence | M11: =RANDBETWEEN(25,45) -> 26 | N11: =RANDBETWEEN(10,30) -> 21 | O11: =RANDBETWEEN(4,15) -> 8
A12: 11 | B12: 37 | C12: 24 | D12: 3 | E12: 10 | F12: =B12*C12*E12 -> 8880 | G12: 10 | H12: =F12*50 -> 444000 | I12: =H12/1000/10/4.2*3.6 -> 38.057143 | J12: =H12/(50-20)*1 -> 14800 | K12: residence | M12: =RANDBETWEEN(25,45) -> 32 | N12: =RANDBETWEEN(10,30) -> 11 | O12: =RANDBETWEEN(4,15) -> 10
A13: 12 | B13: 39 | C13: 12 | D13: 3 | E13: 13 | F13: =B13*C13*E13 -> 6084 | G13: 10 | H13: =F13*50 -> 304200 | I13: =H13/1000/10/4.2*3.6 -> 26.074286 | J13: =H13/(50-20)*1 -> 10140 | K13: residence | M13: =RANDBETWEEN(25,45) -> 40 | N13: =RANDBETWEEN(10,30) -> 29 | O13: =RANDBETWEEN(4,15) -> 6
A14: 13 | B14: 45 | C14: 28 | D14: 3 | E14: 6 | F14: =B14*C14*E14 -> 7560 | G14: 10 | H14: =F14*50 -> 378000 | I14: =H14/1000/10/4.2*3.6 -> 32.4 | J14: =H14/(50-20)*1 -> 12600 | K14: residence | M14: =RANDBETWEEN(25,45) -> 41 | N14: =RANDBETWEEN(10,30) -> 10 | O14: =RANDBETWEEN(4,15) -> 14
... A16: 15 | B16: 34 | C16: 11 | D16: 3 | E16: 11 | F16: =B16*C16*E16 -> 4114 | G16: 10 | H16: =F16*50 -> 205700 | I16: =H16/1000/10/4.2*3.6 -> 17.631429 | J16: =H16/(50-20)*1 -> 6856.6667 | K16: residence | M16: =RANDBETWEEN(25,45) -> 45 | N16: =RANDBETWEEN(10,30) -> 16 | O16: =RANDBETWEEN(4,15) -> 8

Sheet 管径设计
A1: 管段编号 | B1: 计算流量(t/h) | C1: 管段长度(m) | D1: 直径（mm） | E1: 流速 | F1: 比摩阻 | G1: 压力损失（Pa） | H1: 最大压降（Pa） | I1: 最大比摩阻 | J1: 雷诺数 | K1: lamda(阻力平方区用尼古拉兹公式) | L1: 水的密度(kg/m3) | M1: 动力黏度(Pa s) | N1: 总压降
A2: 干路 | L2: 1000 | M2: =1*10^-3 -> 0.001 | N2: =SUM(G3:G17) -> 45606.7
A3: 1,2 | B3: =B4+B20 -> 339.67286 | C3: =Branch!D2 -> 75 | D3: 300 | E3: 1.3 | F3: 57.3 | G3: =C3*F3 -> 4297.5 | J3: =L$2*E3*D3/1000/M$2 -> 390000 | K3: =1/(1.14+2*LOG10((D3/0.5)))^2 -> 0.022301284
A4: 2,3 | B4: =B5+B21 -> 315.37286 | C4: =Branch!D3 -> 93 | D4: 300 | E4: 1.22 | F4: 50.8 | G4: =C4*F4 -> 4724.4 | J4: =L$2*E4*D4/1000/M$2 -> 366000 | K4: =1/(1.14+2*LOG10((D4/0.5)))^2 -> 0.022301284
A5: 3,4 | B5: =B6+B22 -> 293.95286 | C5: =Branch!D4 -> 37 | D5: 300 | E5: 1.11 | F5: 41.7 | G5: =C5*F5 -> 1542.9 | J5: =L$2*E5*D5/1000/M$2 -> 333000 | K5: =1/(1.14+2*LOG10((D5/0.5)))^2 -> 0.022301284
A6: 4,5 | B6: =B7+B23 -> 250.11 | C6: =Branch!D5 -> 72 | D6: 250 | E6: 1.36 | F6: 77.9 | G6: =C6*F6 -> 5608.8 | J6: =L$2*E6*D6/1000/M$2 -> 340000 | K6: =1/(1.14+2*LOG10((D6/0.5)))^2 -> 0.023394735
A7: 5,6 | B7: =B8+B24 -> 239.55 | C7: =Branch!D6 -> 34 | D7: 250 | E7: 1.3 | F7: 71.8 | G7: =C7*F7 -> 2441.2 | J7: =L$2*E7*D7/1000/M$2 -> 325000 | K7: =1/(1.14+2*LOG10((D7/0.5)))^2 -> 0.023394735
A8: 6,7 | B8: =B9+B25 -> 214.05 | C8: =Branch!D7 -> 50 | D8: 250 | E8: 1.14 | F8: 55 | G8: =C8*F8 -> 2750 | J8: =L$2*E8*D8/1000/M$2 -> 285000 | K8: =1/(1.14+2*LOG10((D8/0.5)))^2 -> 0.023394735
A9: 7,8 | B9: =B10+B26 -> 202.01571 | C9: =Branch!D8 -> 50 | D9: 250 | E9: 1.08 | F9: 49.9 | G9: =C9*F9 -> 2495 | J9: =L$2*E9*D9/1000/M$2 -> 270000 | K9: =1/(1.14+2*LOG10((D9/0.5)))^2 -> 0.023394735
A10: 8,9 | B10: =B11+B27 -> 190.23 | C10: =Branch!D9 -> 96 | D10: 250 | E10: 1.03 | F10: 45 | G10: =C10*F10 -> 4320 | J10: =L$2*E10*D10/1000/M$2 -> 257500 | K10: =1/(1.14+2*LOG10((D10/0.5)))^2 -> 0.023394735
A11: 9,10 | B11: =B12+B28 -> 175.81286 | C11: =Branch!D10 -> 83 | D11: 250 | E11: 0.95 | F11: 38.2 | G11: =C11*F11 -> 3170.6 | J11: =L$2*E11*D11/1000/M$2 -> 237500 | K11: =1/(1.14+2*LOG10((D11/0.5)))^2 -> 0.023394735
A12: 10,11 | B12: =B13+B29 -> 165.01286 | C12: =Branch!D11 -> 37 | D12: 250 | E12: 0.89 | F12: 34 | G12: =C12*F12 -> 1258 | J12: =L$2*E12*D12/1000/M$2 -> 222500 | K12: =1/(1.14+2*LOG10((D12/0.5)))^2 -> 0.023394735
A13: 11,12 | B13: =B14+B30 -> 133.96286 | C13: =Branch!D12 -> 76 | D13: 250 | E13: 0.73 | F13: 22.7 | G13: =C13*F13 -> 1725.2 | J13: =L$2*E13*D13/1000/M$2 -> 182500 | K13: =1/(1.14+2*LOG10((D13/0.5)))^2 -> 0.023394735
A14: 12,13 | B14: =B15+B31 -> 95.905714 | C14: =Branch!D13 -> 81 | D14: 200 | E14: 0.82 | F14: 38.2 | G14: =C14*F14 -> 3094.2 | J14: =L$2*E14*D14/1000/M$2 -> 164000 | K14: =1/(1.14+2*LOG10((D14/0.5)))^2 -> 0.024846043
... A16: 14,15 | B16: =B17+B33 -> 37.431429 | C16: =Branch!D15 -> 77 | D16: 150 | E16: 0.61 | F16: 31.8 | G16: =C16*F16 -> 2448.6 | J16: =L$2*E16*D16/1000/M$2 -> 91500 | K16: =1/(1.14+2*LOG10((D16/0.5)))^2 -> 0.026925299
A17: 15,30 | B17: =Building!I16 -> 17.631429 | C17: =Branch!D16 -> 81 | D17: 100 | E17: 0.63 | F17: 57.2 | G17: =C17*F17 -> 4633.2 | J17: =L$2*E17*D17/1000/M$2 -> 63000 | K17: =1/(1.14+2*LOG10((D17/0.5)))^2 -> 0.030329451
A19: 支路
A20: 2,16 | B20: =Building!I2 -> 24.3 | C20: =Branch!D17 -> 38 | D20: 65 | E20: 1.86 | F20: 818.9 | G20: =C20*F20 -> 31118.2 | H20: =N$2-G3 -> 41309.2 | I20: =H20/C20 -> 1087.0842 | J20: =L$2*E20*D20/1000/M$2 -> 120900 | K20: =1/(1.14+2*LOG10((D20/0.5)))^2 -> 0.034705101
A21: 3,17 | B21: =Building!I3 -> 21.42 | C21: =Branch!D18 -> 71 | D21: 65 | E21: 1.55 | F21: 568.7 | G21: =C21*F21 -> 40377.7 | H21: =H20-G4 -> 36584.8 | I21: =H21/C21 -> 515.27887 | J21: =L$2*E21*D21/1000/M$2 -> 100750 | K21: =1/(1.14+2*LOG10((D21/0.5)))^2 -> 0.034705101
A22: 4,18 | B22: =Building!I4 -> 43.842857 | C22: =Branch!D19 -> 40 | D22: 100 | E22: 1.59 | F22: 366.2 | G22: =C22*F22 -> 14648 | H22: =H21-G5 -> 35041.9 | I22: =H22/C22 -> 876.0475 | J22: =L$2*E22*D22/1000/M$2 -> 159000 | K22: =1/(1.14+2*LOG10((D22/0.5)))^2 -> 0.030329451
A23: 5,19 | B23: =Building!I5 -> 10.56 | C23: =Branch!D20 -> 40 | D23: 50 | E23: 1.48 | F23: 791 | G23: =C23*F23 -> 31640 | H23: =H22-G6 -> 29433.1 | I23: =H23/C23 -> 735.8275 | J23: =L$2*E23*D23/1000/M$2 -> 74000 | K23: =1/(1.14+2*LOG10((D23/0.5)))^2 -> 0.037850687
A24: 6,20 | B24: =Building!I6 -> 25.5 | C24: =Branch!D21 -> 78 | D24: 80 | E24: 1.37 | F24: 355 | G24: =C24*F24 -> 27690 | H24: =H23-G7 -> 26991.9 | I24: =H24/C24 -> 346.05 | J24: =L$2*E24*D24/1000/M$2 -> 109600 | K24: =1/(1.14+2*LOG10((D24/0.5)))^2 -> 0.032485498
A25: 7,21 | B25: =Building!I7 -> 12.034286 | C25: =Branch!D22 -> 94 | D25: 65 | E25: 0.93 | F25: 204.7 | G25: =C25*F25 -> 19241.8 | H25: =H24-G8 -> 24241.9 | I25: =H25/C25 -> 257.89255 | J25: =L$2*E25*D25/1000/M$2 -> 60450 | K25: =1/(1.14+2*LOG10((D25/0.5)))^2 -> 0.034705101
A26: 8,22 | B26: =Building!I8 -> 11.785714 | C26: =Branch!D23 -> 32 | D26: 65 | E26: 0.85 | F26: 172 | G26: =C26*F26 -> 5504 | H26: =H25-G9 -> 21746.9 | I26: =H26/C26 -> 679.59063 | J26: =L$2*E26*D26/1000/M$2 -> 55250 | K26: =1/(1.14+2*LOG10((D26/0.5)))^2 -> 0.034705101
A27: 9,23 | B27: =Building!I9 -> 14.417143 | C27: =Branch!D24 -> 61 | D27: 65 | E27: 1.09 | F27: 278.6 | G27: =C27*F27 -> 16994.6 | H27: =H26-G10 -> 17426.9 | I27: =H27/C27 -> 285.68689 | J27: =L$2*E27*D27/1000/M$2 -> 70850 | K27: =1/(1.14+2*LOG10((D27/0.5)))^2 -> 0.034705101
A28: 10,24 | B28: =Building!I10 -> 10.8 | C28: =Branch!D25 -> 46 | D28: 65 | E28: 0.78 | F28: 142 | G28: =C28*F28 -> 6532 | H28: =H27-G11 -> 14256.3 | I28: =H28/C28 -> 309.91957 | J28: =L$2*E28*D28/1000/M$2 -> 50700 | K28: =1/(1.14+2*LOG10((D28/0.5)))^2 -> 0.034705101
A29: 11,25 | B29: =Building!I11 -> 31.05 | C29: =Branch!D26 -> 58 | D29: 100 | E29: 1.14 | F29: 190.4 | G29: =C29*F29 -> 11043.2 | H29: =H28-G12 -> 12998.3 | I29: =H29/C29 -> 224.10862 | J29: =L$2*E29*D29/1000/M$2 -> 114000 | K29: =1/(1.14+2*LOG10((D29/0.5)))^2 -> 0.030329451
A30: 12,26 | B30: =Building!I12 -> 38.057143 | C30: =Branch!D27 -> 33 | D30: 100 | E30: 1.4 | F30: 286 | G30: =C30*F30 -> 9438 | H30: =H29-G13 -> 11273.1 | I30: =H30/C30 -> 341.60909 | J30: =L$2*E30*D30/1000/M$2 -> 140000 | K30: =1/(1.14+2*LOG10((D30/0.5)))^2 -> 0.030329451
A31: 13,27 | B31: =Building!I13 -> 26.074286 | C31: =Branch!D28 -> 45 | D31: 100 | E31: 0.96 | F31: 134 | G31: =C31*F31 -> 6030 | H31: =H30-G14 -> 8178.9 | I31: =H31/C31 -> 181.75333 | J31: =L$2*E31*D31/1000/M$2 -> 96000 | K31: =1/(1.14+2*LOG10((D31/0.5)))^2 -> 0.030329451
A32: 14,28 | B32: =Building!I14 -> 32.4 | C32: =Branch!D29 -> 95 | D32: 125 | E32: 0.76 | F32: 62 | G32: =C32*F32 -> 5890 | H32: =H31-G15 -> 7081.8 | I32: =H32/C32 -> 74.545263 | J32: =L$2*E32*D32/1000/M$2 -> 95000 | K32: =1/(1.14+2*LOG10((D32/0.5)))^2 -> 0.028381136
A33: 15,29 | B33: =Building!I15 -> 19.8 | C33: =Branch!D30 -> 86 | D33: 100 | E33: 0.7 | F33: 71.5 | G33: =C33*F33 -> 6149 | H33: =H32-G16 -> 4633.2 | I33: =H33/C33 -> 53.874419 | J33: =L$2*E33*D33/1000/M$2 -> 70000 | K33: =1/(1.14+2*LOG10((D33/0.5)))^2 -> 0.030329451
A35: 16,46 | B35: =B20 -> 24.3 | C35: =H35/F35 -> 24.423006 | D35: =D20 -> 65 | E35: =E20 -> 1.86 | F35: =F20 -> 818.9 | G35: =C35*F35 -> 20000 | H35: 20000 | I35: 100 | J35: =L$2*E35*D35/1000/M$2 -> 120900 | K35: =1/(1.14+2*LOG10((D35/0.5)))^2 -> 0.034705101
A36: 17,47 | B36: =B21 -> 21.42 | C36: =H36/F36 -> 35.167927 | D36: =D21 -> 65 | E36: =E21 -> 1.55 | F36: =F21 -> 568.7 | G36: =C36*F36 -> 20000 | H36: 20000 | I36: 100 | J36: =L$2*E36*D36/1000/M$2 -> 100750 | K36: =1/(1.14+2*LOG10((D36/0.5)))^2 -> 0.034705101
A37: 18,48 | B37: =B22 -> 43.842857 | C37: =H37/F37 -> 54.614965 | D37: =D22 -> 100 | E37: =E22 -> 1.59 | F37: =F22 -> 366.2 | G37: =C37*F37 -> 20000 | H37: 20000 | I37: 100 | J37: =L$2*E37*D37/1000/M$2 -> 159000 | K37: =1/(1.14+2*LOG10((D37/0.5)))^2 -> 0.030329451
A38: 19,49 | B38: =B23 -> 10.56 | C38: =H38/F38 -> 25.28445 | D38: =D23 -> 50 | E38: =E23 -> 1.48 | F38: =F23 -> 791 | G38: =C38*F38 -> 20000 | H38: 20000 | I38: 100 | J38: =L$2*E38*D38/1000/M$2 -> 74000 | K38: =1/(1.14+2*LOG10((D38/0.5)))^2 -> 0.037850687
A39: 20,50 | B39: =B24 -> 25.5 | C39: =H39/F39 -> 56.338028 | D39: =D24 -> 80 | E39: =E24 -> 1.37 | F39: =F24 -> 355 | G39: =C39*F39 -> 20000 | H39: 20000 | I39: 100 | J39: =L$2*E39*D39/1000/M$2 -> 109600 | K39: =1/(1.14+2*LOG10((D39/0.5)))^2 -> 0.032485498
A40: 21,51 | B40: =B25 -> 12.034286 | C40: =H40/F40 -> 97.703957 | D40: =D25 -> 65 | E40: =E25 -> 0.93 | F40: =F25 -> 204.7 | G40: =C40*F40 -> 20000 | H40: 20000 | J40: =L$2*E40*D40/1000/M$2 -> 60450 | K40: =1/(1.14+2*LOG10((D40/0.5)))^2 -> 0.034705101
A41: 22,52 | B41: =B26 -> 11.785714 | C41: =H41/F41 -> 116.27907 | D41: =D26 -> 65 | E41: =E26 -> 0.85 | F41: =F26 -> 172 | G41: =C41*F41 -> 20000 | H41: 20000 | J41: =L$2*E41*D41/1000/M$2 -> 55250 | K41: =1/(1.14+2*LOG10((D41/0.5)))^2 -> 0.034705101
A42: 23,53 | B42: =B27 -> 14.417143 | C42: =H42/F42 -> 71.787509 | D42: =D27 -> 65 | E42: =E27 -> 1.09 | F42: =F27 -> 278.6 | G42: =C42*F42 -> 20000 | H42: 20000 | J42: =L$2*E42*D42/1000/M$2 -> 70850 | K42: =1/(1.14+2*LOG10((D42/0.5)))^2 -> 0.034705101
A43: 24,54 | B43: =B28 -> 10.8 | C43: =H43/F43 -> 140.84507 | D43: =D28 -> 65 | E43: =E28 -> 0.78 | F43: =F28 -> 142 | G43: =C43*F43 -> 20000 | H43: 20000 | J43: =L$2*E43*D43/1000/M$2 -> 50700 | K43: =1/(1.14+2*LOG10((D43/0.5)))^2 -> 0.034705101
...
